Workbook

Sheet Osiris Results
A1: sample_id | B1: is_hallucination | C1: confidence | D1: osiris_response | E1: has_context | F1: ground_truth | G1: evaluation_decision | H1: TP | I1: FP | J1: FN | K1: TN
A2: 1 | B2: FALSE | C2: 0.9 | D2: supported | E2: TRUE | F2: TRUE | G2: TRUE | H2: =IF(AND(G2=FALSE, B2=TRUE), 1, 0) -> 0 | I2: =IF(AND(G2=TRUE, B2=TRUE), 1, 0) -> 0 | J2: =IF(AND(G2=FALSE, B2=FALSE), 1, 0) -> 0 | K2: =IF(AND(G2=TRUE, B2=FALSE), 1, 0) -> 1
A3: 2 | B3: FALSE | C3: 0.9 | D3: supported | E3: TRUE | F3: TRUE | G3: FALSE | H3: =IF(AND(G3=FALSE, B3=TRUE), 1, 0) -> 0 | I3: =IF(AND(G3=TRUE, B3=TRUE), 1, 0) -> 0 | J3: =IF(AND(G3=FALSE, B3=FALSE), 1, 0) -> 1 | K3: =IF(AND(G3=TRUE, B3=FALSE), 1, 0) -> 0
A4: 3 | B4: FALSE | C4: 0.9 | D4: supported | E4: TRUE | F4: TRUE | G4: TRUE | H4: =IF(AND(G4=FALSE, B4=TRUE), 1, 0) -> 0 | I4: =IF(AND(G4=TRUE, B4=TRUE), 1, 0) -> 0 | J4: =IF(AND(G4=FALSE, B4=FALSE), 1, 0) -> 0 | K4: =IF(AND(G4=TRUE, B4=FALSE), 1, 0) -> 1
A5: 4 | B5: FALSE | C5: 0.9 | D5: supported | E5: TRUE | F5: TRUE | G5: TRUE | H5: =IF(AND(G5=FALSE, B5=TRUE), 1, 0) -> 0 | I5: =IF(AND(G5=TRUE, B5=TRUE), 1, 0) -> 0 | J5: =IF(AND(G5=FALSE, B5=FALSE), 1, 0) -> 0 | K5: =IF(AND(G5=TRUE, B5=FALSE), 1, 0) -> 1
A6: 5 | B6: FALSE | C6: 0.9 | D6: supported | E6: TRUE | F6: TRUE | G6: TRUE | H6: =IF(AND(G6=FALSE, B6=TRUE), 1, 0) -> 0 | I6: =IF(AND(G6=TRUE, B6=TRUE), 1, 0) -> 0 | J6: =IF(AND(G6=FALSE, B6=FALSE), 1, 0) -> 0 | K6: =IF(AND(G6=TRUE, B6=FALSE), 1, 0) -> 1
A7: 6 | B7: FALSE | C7: 0.9 | D7: supported | E7: TRUE | F7: TRUE | G7: TRUE | H7: =IF(AND(G7=FALSE, B7=TRUE), 1, 0) -> 0 | I7: =IF(AND(G7=TRUE, B7=TRUE), 1, 0) -> 0 | J7: =IF(AND(G7=FALSE, B7=FALSE), 1, 0) -> 0 | K7: =IF(AND(G7=TRUE, B7=FALSE), 1, 0) -> 1
A8: 7 | B8: FALSE | C8: 0.9 | D8: supported | E8: TRUE | F8: TRUE | G8: TRUE | H8: =IF(AND(G8=FALSE, B8=TRUE), 1, 0) -> 0 | I8: =IF(AND(G8=TRUE, B8=TRUE), 1, 0) -> 0 | J8: =IF(AND(G8=FALSE, B8=FALSE), 1, 0) -> 0 | K8: =IF(AND(G8=TRUE, B8=FALSE), 1, 0) -> 1
A9: 8 | B9: FALSE | C9: 0.9 | D9: supported | E9: TRUE | F9: TRUE | G9: TRUE | H9: =IF(AND(G9=FALSE, B9=TRUE), 1, 0) -> 0 | I9: =IF(AND(G9=TRUE, B9=TRUE), 1, 0) -> 0 | J9: =IF(AND(G9=FALSE, B9=FALSE), 1, 0) -> 0 | K9: =IF(AND(G9=TRUE, B9=FALSE), 1, 0) -> 1
A10: 9 | B10: FALSE | C10: 0.9 | D10: supported | E10: TRUE | F10: TRUE | G10: TRUE | H10: =IF(AND(G10=FALSE, B10=TRUE), 1, 0) -> 0 | I10: =IF(AND(G10=TRUE, B10=TRUE), 1, 0) -> 0 | J10: =IF(AND(G10=FALSE, B10=FALSE), 1, 0) -> 0 | K10: =IF(AND(G10=TRUE, B10=FALSE), 1, 0) -> 1
A11: 10 | B11: FALSE | C11: 0.9 | D11: supported | E11: TRUE | F11: TRUE | G11: TRUE | H11: =IF(AND(G11=FALSE, B11=TRUE), 1, 0) -> 0 | I11: =IF(AND(G11=TRUE, B11=TRUE), 1, 0) -> 0 | J11: =IF(AND(G11=FALSE, B11=FALSE), 1, 0) -> 0 | K11: =IF(AND(G11=TRUE, B11=FALSE), 1, 0) -> 1
A12: 11 | B12: FALSE | C12: 0.9 | D12: supported | E12: TRUE | F12: TRUE | G12: FALSE | H12: =IF(AND(G12=FALSE, B12=TRUE), 1, 0) -> 0 | I12: =IF(AND(G12=TRUE, B12=TRUE), 1, 0) -> 0 | J12: =IF(AND(G12=FALSE, B12=FALSE), 1, 0) -> 1 | K12: =IF(AND(G12=TRUE, B12=FALSE), 1, 0) -> 0
A13: 12 | B13: FALSE | C13: 0.9 | D13: supported | E13: TRUE | F13: TRUE | G13: TRUE | H13: =IF(AND(G13=FALSE, B13=TRUE), 1, 0) -> 0 | I13: =IF(AND(G13=TRUE, B13=TRUE), 1, 0) -> 0 | J13: =IF(AND(G13=FALSE, B13=FALSE), 1, 0) -> 0 | K13: =IF(AND(G13=TRUE, B13=FALSE), 1, 0) -> 1
... A234: 233 | B234: FALSE | C234: 0.9 | D234: supported | E234: TRUE | F234: TRUE | G234: TRUE | H234: =IF(AND(G234=FALSE, B234=TRUE), 1, 0) -> 0 | I234: =IF(AND(G234=TRUE, B234=TRUE), 1, 0) -> 0 | J234: =IF(AND(G234=FALSE, B234=FALSE), 1, 0) -> 0 | K234: =IF(AND(G234=TRUE, B234=FALSE), 1, 0) -> 1
A235: 234 | B235: FALSE | C235: 0.9 | D235: supported | E235: TRUE | F235: TRUE | G235: None | H235: =IF(AND(G235=FALSE, B235=TRUE), 1, 0) -> 0 | I235: =IF(AND(G235=TRUE, B235=TRUE), 1, 0) -> 0 | J235: =IF(AND(G235=FALSE, B235=FALSE), 1, 0) -> 0 | K235: =IF(AND(G235=TRUE, B235=FALSE), 1, 0) -> 0
A236: 235 | B236: FALSE | C236: 0.9 | D236: supported | E236: TRUE | F236: TRUE | G236: TRUE | H236: =IF(AND(G236=FALSE, B236=TRUE), 1, 0) -> 0 | I236: =IF(AND(G236=TRUE, B236=TRUE), 1, 0) -> 0 | J236: =IF(AND(G236=FALSE, B236=FALSE), 1, 0) -> 0 | K236: =IF(AND(G236=TRUE, B236=FALSE), 1, 0) -> 1
A237: 236 | B237: FALSE | C237: 0.9 | D237: supported | E237: TRUE | F237: TRUE | G237: TRUE | H237: =IF(AND(G237=FALSE, B237=TRUE), 1, 0) -> 0 | I237: =IF(AND(G237=TRUE, B237=TRUE), 1, 0) -> 0 | J237: =IF(AND(G237=FALSE, B237=FALSE), 1, 0) -> 0 | K237: =IF(AND(G237=TRUE, B237=FALSE), 1, 0) -> 1
A238: 237 | B238: FALSE | C238: 0.9 | D238: supported | E238: TRUE | F238: TRUE | G238: TRUE | H238: =IF(AND(G238=FALSE, B238=TRUE), 1, 0) -> 0 | I238: =IF(AND(G238=TRUE, B238=TRUE), 1, 0) -> 0 | J238: =IF(AND(G238=FALSE, B238=FALSE), 1, 0) -> 0 | K238: =IF(AND(G238=TRUE, B238=FALSE), 1, 0) -> 1
A239: 238 | B239: FALSE | C239: 0.9 | D239: supported | E239: TRUE | F239: TRUE | G239: TRUE | H239: =IF(AND(G239=FALSE, B239=TRUE), 1, 0) -> 0 | I239: =IF(AND(G239=TRUE, B239=TRUE), 1, 0) -> 0 | J239: =IF(AND(G239=FALSE, B239=FALSE), 1, 0) -> 0 | K239: =IF(AND(G239=TRUE, B239=FALSE), 1, 0) -> 1
A240: 239 | B240: FALSE | C240: 0.9 | D240: supported | E240: TRUE | F240: TRUE | G240: TRUE | H240: =IF(AND(G240=FALSE, B240=TRUE), 1, 0) -> 0 | I240: =IF(AND(G240=TRUE, B240=TRUE), 1, 0) -> 0 | J240: =IF(AND(G240=FALSE, B240=FALSE), 1, 0) -> 0 | K240: =IF(AND(G240=TRUE, B240=FALSE), 1, 0) -> 1
A241: 240 | B241: FALSE | C241: 0.9 | D241: supported | E241: TRUE | F241: TRUE | G241: TRUE | H241: =IF(AND(G241=FALSE, B241=TRUE), 1, 0) -> 0 | I241: =IF(AND(G241=TRUE, B241=TRUE), 1, 0) -> 0 | J241: =IF(AND(G241=FALSE, B241=FALSE), 1, 0) -> 0 | K241: =IF(AND(G241=TRUE, B241=FALSE), 1, 0) -> 1
A242: 241 | B242: FALSE | C242: 0.9 | D242: supported | E242: TRUE | F242: TRUE | G242: TRUE | H242: =IF(AND(G242=FALSE, B242=TRUE), 1, 0) -> 0 | I242: =IF(AND(G242=TRUE, B242=TRUE), 1, 0) -> 0 | J242: =IF(AND(G242=FALSE, B242=FALSE), 1, 0) -> 0 | K242: =IF(AND(G242=TRUE, B242=FALSE), 1, 0) -> 1
A243: 242 | B243: FALSE | C243: 0.9 | D243: supported | E243: TRUE | F243: TRUE | G243: TRUE | H243: =IF(AND(G243=FALSE, B243=TRUE), 1, 0) -> 0 | I243: =IF(AND(G243=TRUE, B243=TRUE), 1, 0) -> 0 | J243: =IF(AND(G243=FALSE, B243=FALSE), 1, 0) -> 0 | K243: =IF(AND(G243=TRUE, B243=FALSE), 1, 0) -> 1
A244: 243 | B244: FALSE | C244: 0.9 | D244: supported | E244: TRUE | F244: TRUE | G244: TRUE | H244: =IF(AND(G244=FALSE, B244=TRUE), 1, 0) -> 0 | I244: =IF(AND(G244=TRUE, B244=TRUE), 1, 0) -> 0 | J244: =IF(AND(G244=FALSE, B244=FALSE), 1, 0) -> 0 | K244: =IF(AND(G244=TRUE, B244=FALSE), 1, 0) -> 1
A245: 244 | B245: FALSE | C245: 0.9 | D245: supported | E245: TRUE | F245: TRUE | G245: TRUE | H245: =IF(AND(G245=FALSE, B245=TRUE), 1, 0) -> 0 | I245: =IF(AND(G245=TRUE, B245=TRUE), 1, 0) -> 0 | J245: =IF(AND(G245=FALSE, B245=FALSE), 1, 0) -> 0 | K245: =IF(AND(G245=TRUE, B245=FALSE), 1, 0) -> 1
A246: 245 | B246: FALSE | C246: 0.9 | D246: supported | E246: TRUE | F246: TRUE | G246: TRUE | H246: =IF(AND(G246=FALSE, B246=TRUE), 1, 0) -> 0 | I246: =IF(AND(G246=TRUE, B246=TRUE), 1, 0) -> 0 | J246: =IF(AND(G246=FALSE, B246=FALSE), 1, 0) -> 0 | K246: =IF(AND(G246=TRUE, B246=FALSE), 1, 0) -> 1
A247: 246 | B247: FALSE | C247: 0.9 | D247: supported | E247: TRUE | F247: TRUE | G247: FALSE | H247: =IF(AND(G247=FALSE, B247=TRUE), 1, 0) -> 0 | I247: =IF(AND(G247=TRUE, B247=TRUE), 1, 0) -> 0 | J247: =IF(AND(G247=FALSE, B247=FALSE), 1, 0) -> 1 | K247: =IF(AND(G247=TRUE, B247=FALSE), 1, 0) -> 0
... A263: 262 | B263: FALSE | C263: 0.9 | D263: supported | E263: TRUE | F263: TRUE | G263: TRUE | H263: =IF(AND(G263=FALSE, B263=TRUE), 1, 0) -> 0 | I263: =IF(AND(G263=TRUE, B263=TRUE), 1, 0) -> 0 | J263: =IF(AND(G263=FALSE, B263=FALSE), 1, 0) -> 0 | K263: =IF(AND(G263=TRUE, B263=FALSE), 1, 0) -> 1
A264: 263 | B264: FALSE | C264: 0.9 | D264: supported | E264: TRUE | F264: TRUE | G264: None | H264: =IF(AND(G264=FALSE, B264=TRUE), 1, 0) -> 0 | I264: =IF(AND(G264=TRUE, B264=TRUE), 1, 0) -> 0 | J264: =IF(AND(G264=FALSE, B264=FALSE), 1, 0) -> 0 | K264: =IF(AND(G264=TRUE, B264=FALSE), 1, 0) -> 0
A265: 264 | B265: FALSE | C265: 0.9 | D265: supported | E265: TRUE | F265: TRUE | G265: TRUE | H265: =IF(AND(G265=FALSE, B265=TRUE), 1, 0) -> 0 | I265: =IF(AND(G265=TRUE, B265=TRUE), 1, 0) -> 0 | J265: =IF(AND(G265=FALSE, B265=FALSE), 1, 0) -> 0 | K265: =IF(AND(G265=TRUE, B265=FALSE), 1, 0) -> 1
A266: 265 | B266: FALSE | C266: 0.9 | D266: supported | E266: TRUE | F266: TRUE | G266: TRUE | H266: =IF(AND(G266=FALSE, B266=TRUE), 1, 0) -> 0 | I266: =IF(AND(G266=TRUE, B266=TRUE), 1, 0) -> 0 | J266: =IF(AND(G266=FALSE, B266=FALSE), 1, 0) -> 0 | K266: =IF(AND(G266=TRUE, B266=FALSE), 1, 0) -> 1
A267: 266 | B267: FALSE | C267: 0.9 | D267: supported | E267: TRUE | F267: TRUE | G267: TRUE | H267: =IF(AND(G267=FALSE, B267=TRUE), 1, 0) -> 0 | I267: =IF(AND(G267=TRUE, B267=TRUE), 1, 0) -> 0 | J267: =IF(AND(G267=FALSE, B267=FALSE), 1, 0) -> 0 | K267: =IF(AND(G267=TRUE, B267=FALSE), 1, 0) -> 1
A268: 267 | B268: FALSE | C268: 0.9 | D268: supported | E268: TRUE | F268: TRUE | G268: TRUE | H268: =IF(AND(G268=FALSE, B268=TRUE), 1, 0) -> 0 | I268: =IF(AND(G268=TRUE, B268=TRUE), 1, 0) -> 0 | J268: =IF(AND(G268=FALSE, B268=FALSE), 1, 0) -> 0 | K268: =IF(AND(G268=TRUE, B268=FALSE), 1, 0) -> 1
A269: 268 | B269: FALSE | C269: 0.9 | D269: supported | E269: TRUE | F269: TRUE | G269: FALSE | H269: =IF(AND(G269=FALSE, B269=TRUE), 1, 0) -> 0 | I269: =IF(AND(G269=TRUE, B269=TRUE), 1, 0) -> 0 | J269: =IF(AND(G269=FALSE, B269=FALSE), 1, 0) -> 1 | K269: =IF(AND(G269=TRUE, B269=FALSE), 1, 0) -> 0
A270: 269 | B270: FALSE | C270: 0.9 | D270: supported | E270: TRUE | F270: TRUE | G270: TRUE | H270: =IF(AND(G270=FALSE, B270=TRUE), 1, 0) -> 0 | I270: =IF(AND(G270=TRUE, B270=TRUE), 1, 0) -> 0 | J270: =IF(AND(G270=FALSE, B270=FALSE), 1, 0) -> 0 | K270: =IF(AND(G270=TRUE, B270=FALSE), 1, 0) -> 1
A271: 270 | B271: FALSE | C271: 0.9 | D271: supported | E271: TRUE | F271: TRUE | G271: TRUE | H271: =IF(AND(G271=FALSE, B271=TRUE), 1, 0) -> 0 | I271: =IF(AND(G271=TRUE, B271=TRUE), 1, 0) -> 0 | J271: =IF(AND(G271=FALSE, B271=FALSE), 1, 0) -> 0 | K271: =IF(AND(G271=TRUE, B271=FALSE), 1, 0) -> 1
A272: 271 | B272: FALSE | C272: 0.9 | D272: supported | E272: TRUE | F272: TRUE | G272: TRUE | H272: =IF(AND(G272=FALSE, B272=TRUE), 1, 0) -> 0 | I272: =IF(AND(G272=TRUE, B272=TRUE), 1, 0) -> 0 | J272: =IF(AND(G272=FALSE, B272=FALSE), 1, 0) -> 0 | K272: =IF(AND(G272=TRUE, B272=FALSE), 1, 0) -> 1
A273: 272 | B273: FALSE | C273: 0.9 | D273: supported | E273: TRUE | F273: TRUE | G273: TRUE | H273: =IF(AND(G273=FALSE, B273=TRUE), 1, 0) -> 0 | I273: =IF(AND(G273=TRUE, B273=TRUE), 1, 0) -> 0 | J273: =IF(AND(G273=FALSE, B273=FALSE), 1, 0) -> 0 | K273: =IF(AND(G273=TRUE, B273=FALSE), 1, 0) -> 1
A274: 273 | B274: FALSE | C274: 0.9 | D274: supported | E274: TRUE | F274: TRUE | G274: TRUE | H274: =IF(AND(G274=FALSE, B274=TRUE), 1, 0) -> 0 | I274: =IF(AND(G274=TRUE, B274=TRUE), 1, 0) -> 0 | J274: =IF(AND(G274=FALSE, B274=FALSE), 1, 0) -> 0 | K274: =IF(AND(G274=TRUE, B274=FALSE), 1, 0) -> 1
A275: 274 | B275: FALSE | C275: 0.9 | D275: supported | E275: TRUE | F275: TRUE | G275: TRUE | H275: =IF(AND(G275=FALSE, B275=TRUE), 1, 0) -> 0 | I275: =IF(AND(G275=TRUE, B275=TRUE), 1, 0) -> 0 | J275: =IF(AND(G275=FALSE, B275=FALSE), 1, 0) -> 0 | K275: =IF(AND(G275=TRUE, B275=FALSE), 1, 0) -> 1
...

Sheet Stats
A1: Osiris Stats - Hallucination | D1: Actual Stats | G1: Osiris Alt Stats - Correct
A2: Total Valid | B2: 794 | D2: Correct | E2: =COUNTIF('Osiris Results'!$G$2:$G$799, TRUE) -> 670 | G2: Total Valid | H2: 794
A3: True Positive | B3: ='Osiris Results'!H801 -> 22 | D3: Incorrect | E3: =COUNTIF('Osiris Results'!$G$2:$G$799, FALSE) -> 124 | G3: True Positive | H3: 669
A4: False Positive | B4: ='Osiris Results'!I801 -> 1 | D4: Indeterminate | E4: =COUNTIF('Osiris Results'!$G$2:$G$799, "None") -> 4 | G4: False Positive | H4: 102
A5: False Negative | B5: ='Osiris Results'!J801 -> 102 | D5: Total Valid | E5: 794 | G5: False Negative | H5: 1
A6: True Negative | B6: ='Osiris Results'!K801 -> 669 | D6: Accuracy | E6: =E2/E5 -> 0.84382872 | G6: True Negative | H6: 22
A7: Accuracy | B7: =(B3+B6)/B2 -> 0.87027708 | G7: Accuracy | H7: =(H3+H6)/H2 -> 0.87027708
A8: Precision | B8: =(B3)/(B3+B4) -> 0.95652174 | G8: Precision | H8: =(H3)/(H3+H4) -> 0.86770428
A9: Recall | B9: =B3/(B3+B5) -> 0.17741935 | G9: Recall | H9: =H3/(H3+H5) -> 0.99850746
A10: F1 Score | B10: =(2 * B8 * B9)/(B8 + B9) -> 0.29931973 | G10: F1 Score | H10: =(2 * H8 * H9)/(H8 + H9) -> 0.92852186
A12: TRUE | B12: Hallucination | G12: TRUE | H12: Correct
A13: True Positve | B13: Is/Pred H | C13: ED=F, IH=T | G13: True Positve | H13: Is/Pred C | I13: ED=T, IH=F
A14: True Negative | B14: C/Pred C | C14: ED=T, IH=F | G14: True Negative | H14: H/Pred H | I14: ED=F, IH=T
A15: False Positive | B15: C/Pred H | C15: ED=T, IH=T | G15: False Positive | H15: H/Pred C | I15: ED=F, IH=F
A16: False Negative | B16: Is/Pred C | C16: ED=F, IH=F | G16: False Negative | H16: Is/Pred H | I16: ED=T, IH=T

Sheet Osiris Results-2
A1: sample_id | B1: is_hallucination | C1: confidence | D1: osiris_response | E1: has_context | F1: ground_truth | G1: evaluation_decision | H1: TP | I1: FP | J1: FN | K1: TN
A2: 1 | B2: FALSE | C2: 0.9 | D2: supported | E2: TRUE | F2: TRUE | G2: TRUE | H2: =IF(AND(G2=FALSE, B2=TRUE), 1, 0) -> 0 | I2: =IF(AND(G2=TRUE, B2=TRUE), 1, 0) -> 0 | J2: =IF(AND(G2=FALSE, B2=FALSE), 1, 0) -> 0 | K2: =IF(AND(G2=TRUE, B2=FALSE), 1, 0) -> 1
A3: 2 | B3: FALSE | C3: 0.9 | D3: supported | E3: TRUE | F3: TRUE | G3: FALSE | H3: =IF(AND(G3=FALSE, B3=TRUE), 1, 0) -> 0 | I3: =IF(AND(G3=TRUE, B3=TRUE), 1, 0) -> 0 | J3: =IF(AND(G3=FALSE, B3=FALSE), 1, 0) -> 1 | K3: =IF(AND(G3=TRUE, B3=FALSE), 1, 0) -> 0
A4: 3 | B4: FALSE | C4: 0.9 | D4: supported | E4: TRUE | F4: TRUE | G4: TRUE | H4: =IF(AND(G4=FALSE, B4=TRUE), 1, 0) -> 0 | I4: =IF(AND(G4=TRUE, B4=TRUE), 1, 0) -> 0 | J4: =IF(AND(G4=FALSE, B4=FALSE), 1, 0) -> 0 | K4: =IF(AND(G4=TRUE, B4=FALSE), 1, 0) -> 1
A5: 4 | B5: FALSE | C5: 0.9 | D5: supported | E5: TRUE | F5: TRUE | G5: TRUE | H5: =IF(AND(G5=FALSE, B5=TRUE), 1, 0) -> 0 | I5: =IF(AND(G5=TRUE, B5=TRUE), 1, 0) -> 0 | J5: =IF(AND(G5=FALSE, B5=FALSE), 1, 0) -> 0 | K5: =IF(AND(G5=TRUE, B5=FALSE), 1, 0) -> 1
A6: 5 | B6: FALSE | C6: 0.9 | D6: supported | E6: TRUE | F6: TRUE | G6: TRUE | H6: =IF(AND(G6=FALSE, B6=TRUE), 1, 0) -> 0 | I6: =IF(AND(G6=TRUE, B6=TRUE), 1, 0) -> 0 | J6: =IF(AND(G6=FALSE, B6=FALSE), 1, 0) -> 0 | K6: =IF(AND(G6=TRUE, B6=FALSE), 1, 0) -> 1
A7: 6 | B7: FALSE | C7: 0.9 | D7: supported | E7: TRUE | F7: TRUE | G7: TRUE | H7: =IF(AND(G7=FALSE, B7=TRUE), 1, 0) -> 0 | I7: =IF(AND(G7=TRUE, B7=TRUE), 1, 0) -> 0 | J7: =IF(AND(G7=FALSE, B7=FALSE), 1, 0) -> 0 | K7: =IF(AND(G7=TRUE, B7=FALSE), 1, 0) -> 1
A8: 7 | B8: FALSE | C8: 0.9 | D8: supported | E8: TRUE | F8: TRUE | G8: TRUE | H8: =IF(AND(G8=FALSE, B8=TRUE), 1, 0) -> 0 | I8: =IF(AND(G8=TRUE, B8=TRUE), 1, 0) -> 0 | J8: =IF(AND(G8=FALSE, B8=FALSE), 1, 0) -> 0 | K8: =IF(AND(G8=TRUE, B8=FALSE), 1, 0) -> 1
A9: 8 | B9: FALSE | C9: 0.9 | D9: supported | E9: TRUE | F9: TRUE | G9: TRUE | H9: =IF(AND(G9=FALSE, B9=TRUE), 1, 0) -> 0 | I9: =IF(AND(G9=TRUE, B9=TRUE), 1, 0) -> 0 | J9: =IF(AND(G9=FALSE, B9=FALSE), 1, 0) -> 0 | K9: =IF(AND(G9=TRUE, B9=FALSE), 1, 0) -> 1
A10: 9 | B10: FALSE | C10: 0.9 | D10: supported | E10: TRUE | F10: TRUE | G10: TRUE | H10: =IF(AND(G10=FALSE, B10=TRUE), 1, 0) -> 0 | I10: =IF(AND(G10=TRUE, B10=TRUE), 1, 0) -> 0 | J10: =IF(AND(G10=FALSE, B10=FALSE), 1, 0) -> 0 | K10: =IF(AND(G10=TRUE, B10=FALSE), 1, 0) -> 1
A11: 10 | B11: FALSE | C11: 0.9 | D11: supported | E11: TRUE | F11: TRUE | G11: TRUE | H11: =IF(AND(G11=FALSE, B11=TRUE), 1, 0) -> 0 | I11: =IF(AND(G11=TRUE, B11=TRUE), 1, 0) -> 0 | J11: =IF(AND(G11=FALSE, B11=FALSE), 1, 0) -> 0 | K11: =IF(AND(G11=TRUE, B11=FALSE), 1, 0) -> 1
A12: 11 | B12: FALSE | C12: 0.9 | D12: supported | E12: TRUE | F12: TRUE | G12: FALSE | H12: =IF(AND(G12=FALSE, B12=TRUE), 1, 0) -> 0 | I12: =IF(AND(G12=TRUE, B12=TRUE), 1, 0) -> 0 | J12: =IF(AND(G12=FALSE, B12=FALSE), 1, 0) -> 1 | K12: =IF(AND(G12=TRUE, B12=FALSE), 1, 0) -> 0
A13: 12 | B13: FALSE | C13: 0.9 | D13: supported | E13: TRUE | F13: TRUE | G13: TRUE | H13: =IF(AND(G13=FALSE, B13=TRUE), 1, 0) -> 0 | I13: =IF(AND(G13=TRUE, B13=TRUE), 1, 0) -> 0 | J13: =IF(AND(G13=FALSE, B13=FALSE), 1, 0) -> 0 | K13: =IF(AND(G13=TRUE, B13=FALSE), 1, 0) -> 1
... A795: 794 | B795: FALSE | C795: 0.9 | D795: supported | E795: TRUE | F795: TRUE | G795: TRUE | H795: =IF(AND(G795=FALSE, B795=TRUE), 1, 0) -> 0 | I795: =IF(AND(G795=TRUE, B795=TRUE), 1, 0) -> 0 | J795: =IF(AND(G795=FALSE, B795=FALSE), 1, 0) -> 0 | K795: =IF(AND(G795=TRUE, B795=FALSE), 1, 0) -> 1
A797: Total | H797: =SUM(H2:H795) -> 22 | I797: =SUM(I2:I795) -> 1 | J797: =SUM(J2:J795) -> 102 | K797: =SUM(K2:K795) -> 669

Sheet Stats-2
A1: Osiris Stats - Hallucination | D1: Actual Stats | G1: Osiris Alt Stats - Correct
A2: Total Valid | B2: 794 | D2: Correct | E2: =COUNTIF('Osiris Results-2'!$G$2:$G$795, TRUE) -> 670 | G2: Total Valid | H2: 794
A3: True Positive | B3: ='Osiris Results-2'!H797 -> 22 | D3: Incorrect | E3: =COUNTIF('Osiris Results-2'!$G$2:$G$795, FALSE) -> 124 | G3: True Positive | H3: 669
A4: False Positive | B4: ='Osiris Results-2'!I797 -> 1 | D4: Total Valid | E4: 794 | G4: False Positive | H4: 102
A5: False Negative | B5: ='Osiris Results-2'!J797 -> 102 | D5: Accuracy | E5: =E2/E4 -> 0.84382872 | G5: False Negative | H5: 1
A6: True Negative | B6: ='Osiris Results-2'!K797 -> 669 | G6: True Negative | H6: 22
A7: Accuracy | B7: =(B3+B6)/B2 -> 0.87027708 | G7: Accuracy | H7: =(H3+H6)/H2 -> 0.87027708
A8: Precision | B8: =(B3)/(B3+B4) -> 0.95652174 | G8: Precision | H8: =(H3)/(H3+H4) -> 0.86770428
A9: Recall | B9: =B3/(B3+B5) -> 0.17741935 | G9: Recall | H9: =H3/(H3+H5) -> 0.99850746
A10: F1 Score | B10: =(2 * B8 * B9)/(B8 + B9) -> 0.29931973 | G10: F1 Score | H10: =(2 * H8 * H9)/(H8 + H9) -> 0.92852186
A12: TRUE | B12: Hallucination | G12: TRUE | H12: Correct
A13: True Positve | B13: Is/Pred H | C13: ED=F, IH=T | G13: True Positve | H13: Is/Pred C | I13: ED=T, IH=F
A14: True Negative | B14: C/Pred C | C14: ED=T, IH=F | G14: True Negative | H14: H/Pred H | I14: ED=F, IH=T
A15: False Positive | B15: C/Pred H | C15: ED=T, IH=T | G15: False Positive | H15: H/Pred C | I15: ED=F, IH=F
A16: False Negative | B16: Is/Pred C | C16: ED=F, IH=F | G16: False Negative | H16: Is/Pred H | I16: ED=T, IH=T

Sheet OptiLLM Results
A1: Model | B1: Flash Lite 2.5 | C1: Flash 2.5 | D1: Gemma3-27b | E1: Qwen2.5-7b-i | F1: Qwen2.5-3b-i | G1: LLama3.2-3b-i | H1: GPT4o-mini
A2: Prompt
A3: Naïve | B3: 0.3358 | C3: ? | D3: 0.2985 | E3: 0.1699 | F3: ? | G3: ? | H3: ?
A4: Oracle with Memory Plugin? | B4: -
A5: Oracle | B5: 0.6978 | C5: ? | D5: 0.642 | E5: 0.5631 | F5: ? | G5: ? | H5: ?
A6: Oracle + CoT | B6: 0.8187 | C6: ? | D6: ? | E6: ? | F6: ? | G6: ? | H6: ?
A9: Preprocessing | B9: Questions
A10: FRAMES base (None) | B10: 824
A11: All Wikipedia Content (AWC) | B11: 822 | C11: Note: Two questions reference deleted Wikipedia articles are were removed
A12: Context reduction (CR)
A13: AWC + CR | C13: Note: Non-Google Gemini models do not have a big enough context window size to accept all Wikipedia content, must be compressed/summarized
A16: FRAMES Categories
A17: Multiple Constraints
A18: Numerical Reasoning
A19: Post Processing
A20: Tabular Reasoning
A21: Temporal Reasoning
A24: Osiris Results | B24: Based on 798 questions | D24: Note: 24 questions purged due to output token size too big (> 4k tokens)
B25: See Stats-2 tab
